<?xml version="1.0"?>

<robot name="gen3_arm" xmlns:xacro="http://ros.org/wiki/xacro">

  <!-- Propagate last link name information because it is the gripper's parent link -->
  <xacro:property name="last_arm_link" value="end_effector_link"/>

  <xacro:macro name="load_arm" params="parent:='' *origin">

     <!-- GROUND LINK -->
     <link name="base_link">
        <visual>
          <origin xyz="0 0 0" rpy="0 0 0" />
          <geometry>
            <box size="0.001 0.001 0.001" />
          </geometry>
          <material name="Cyan">
            <color rgba="0 1.0 1.0 1.0"/>
          </material>
        </visual>
<!--         <collision>
          <origin xyz="0 0 0" rpy="0 0 0" />
          <geometry>
            <mesh filename="package://kortex_description/arms/gen3/meshes/base_link.STL" />
          </geometry>
        </collision> -->
    </link>

    <!-- MOBILE BASE LINKS -->
    <link name="x_prismatic">
        <visual>
          <origin xyz="0 0 0" rpy="0 0 0" />
          <geometry>
            <box size="0.001 0.001 0.001" />
          </geometry>
          <material name="Cyan">
            <color rgba="0 1.0 1.0 1.0"/>
          </material>
        </visual>
<!--         <collision>
          <origin xyz="0 0 0" rpy="0 0 0" />
          <geometry>
            <mesh filename="package://kortex_description/arms/gen3/meshes/base_link.STL" />
          </geometry>
        </collision> -->
    </link>

    <link name="y_prismatic">
        <visual>
          <origin xyz="0 0 0" rpy="0 0 0" />
          <geometry>
            <box size="0.001 0.001 0.001" />
          </geometry>
          <material name="Cyan">
            <color rgba="0 1.0 1.0 1.0"/>
          </material>
        </visual>
<!--         <collision>
          <origin xyz="0 0 0" rpy="0 0 0" />
          <geometry>
            <mesh filename="package://kortex_description/arms/gen3/meshes/base_link.STL" />
          </geometry>
        </collision> -->
    </link>

      <!-- MOBILE BASE + LINK 0 OF KINOVA ARM -->
      <link name="mmp_base">
        <inertial>
          <origin xyz="0.0 0.0 0.1757" rpy="0 0 0" />
          <mass value="64.6" />
          <inertia ixx="1.721" ixy="0.0" ixz="0.0" iyy="1.712" iyz="0.0" izz="2.030" />
        </inertial>
        <visual>
          <origin xyz="0 0 0" rpy="0 0 0" />
          <geometry>
            <mesh filename="package://kortex_description/arms/mmp/meshes/BaseCombo.STL" />
          </geometry>
          <material name="">
            <color rgba="0.75294 0.75294 0.75294 1" />
          </material>
        </visual>
        <collision>
          <origin xyz="0 0 0" rpy="0 0 0" />
          <geometry>
            <mesh filename="package://kortex_description/arms/mmp/meshes/BaseCombo.STL" />
          </geometry>
        </collision>
    </link>


    <link name="shoulder_link">
      <inertial>
        <origin xyz="-2.3E-05 -0.010364 -0.07336" rpy="0 0 0" />
        <mass value="1.3773" />
        <inertia ixx="0.00457" ixy="1E-06" ixz="2E-06" iyy="0.004831" iyz="0.000448" izz="0.001409" />
      </inertial>
      <visual>
        <origin xyz="0 0 0" rpy="0 0 0" />
        <geometry>
          <mesh filename="package://kortex_description/arms/gen3/meshes/shoulder_link.STL" />
        </geometry>
        <material name="">
          <color rgba="0.75294 0.75294 0.75294 1" />
        </material>
      </visual>
      <collision>
        <origin xyz="0 0 0" rpy="0 0 0" />
        <geometry>
          <mesh filename="package://kortex_description/arms/gen3/meshes/shoulder_link.STL" />
        </geometry>
      </collision>
    </link>
  
    <link name="half_arm_1_link">
      <inertial>
        <origin xyz="-4.4E-05 -0.09958 -0.013278" rpy="0 0 0" />
        <mass value="1.1636" />
        <inertia ixx="0.011088" ixy="5E-06" ixz="0" iyy="0.001072" iyz="-0.000691" izz="0.011255" />
      </inertial>
      <visual>
        <origin xyz="0 0 0" rpy="0 0 0" />
        <geometry>
          <mesh filename="package://kortex_description/arms/gen3/meshes/half_arm_1_link.STL" />
        </geometry>
        <material name="">
          <color rgba="0.75294 0.75294 0.75294 1" />
        </material>
      </visual>
      <collision>
        <origin xyz="0 0 0" rpy="0 0 0" />
        <geometry>
          <mesh filename="package://kortex_description/arms/gen3/meshes/half_arm_1_link.STL" />
        </geometry>
      </collision>
    </link>

    <link name="half_arm_2_link">
      <inertial>
        <origin xyz="-4.4E-05 -0.006641 -0.117892" rpy="0 0 0" />
        <mass value="1.1636" />
        <inertia ixx="0.010932" ixy="0" ixz="-7E-06" iyy="0.011127" iyz="0.000606" izz="0.001043" />
      </inertial>
      <visual>
        <origin xyz="0 0 0" rpy="0 0 0" />
        <geometry>
          <mesh filename="package://kortex_description/arms/gen3/meshes/half_arm_2_link.STL" />
        </geometry>
        <material name="">
          <color rgba="0.75294 0.75294 0.75294 1" />
        </material>
      </visual>
      <collision>
        <origin xyz="0 0 0" rpy="0 0 0" />
        <geometry>
          <mesh filename="package://kortex_description/arms/gen3/meshes/half_arm_2_link.STL" />
        </geometry>
      </collision>
    </link>

    <link name="forearm_link">
      <inertial>
        <origin xyz="-1.8E-05 -0.075478 -0.015006" rpy="0 0 0" />
        <mass value="0.9302" />
        <inertia ixx="0.008147" ixy="-1E-06" ixz="0" iyy="0.000631" iyz="-0.0005" izz="0.008316" />
      </inertial>
      <visual>
        <origin xyz="0 0 0" rpy="0 0 0" />
        <geometry>
          <mesh filename="package://kortex_description/arms/gen3/meshes/forearm_link.STL" />
        </geometry>
        <material name="">
          <color rgba="0.75294 0.75294 0.75294 1" />
        </material>
      </visual>
      <collision>
        <origin xyz="0 0 0" rpy="0 0 0" />
        <geometry>
          <mesh filename="package://kortex_description/arms/gen3/meshes/forearm_link.STL" />
        </geometry>
      </collision>
    </link>

    <link name="spherical_wrist_1_link">
      <inertial>
        <origin xyz="1E-06 -0.009432 -0.063883" rpy="0 0 0" />
        <mass value="0.6781" />
        <inertia ixx="0.001596" ixy="0" ixz="0" iyy="0.001607" iyz="0.000256" izz="0.000399" />
      </inertial>
      <visual>
        <origin xyz="0 0 0" rpy="0 0 0" />
        <geometry>
          <mesh filename="package://kortex_description/arms/gen3/meshes/spherical_wrist_1_link.STL" />
        </geometry>
        <material name="">
          <color rgba="0.75294 0.75294 0.75294 1" />
        </material>
      </visual>
      <collision>
        <origin xyz="0 0 0" rpy="0 0 0" />
        <geometry>
          <mesh filename="package://kortex_description/arms/gen3/meshes/spherical_wrist_1_link.STL" />
        </geometry>
      </collision>
    </link>

    <link name="spherical_wrist_2_link">
      <inertial>
        <origin xyz="1E-06 -0.045483 -0.00965" rpy="0 0 0" />
        <mass value="0.6781" />
        <inertia ixx="0.001641" ixy="0" ixz="0" iyy="0.00041" iyz="-0.000278" izz="0.001641" />
      </inertial>
      <visual>
        <origin xyz="0 0 0" rpy="0 0 0" />
        <geometry>
          <mesh filename="package://kortex_description/arms/gen3/meshes/spherical_wrist_2_link.STL" />
        </geometry>
        <material name="">
          <color rgba="0.75294 0.75294 0.75294 1" />
        </material>
      </visual>
      <collision>
        <origin xyz="0 0 0" rpy="0 0 0" />
        <geometry>
          <mesh filename="package://kortex_description/arms/gen3/meshes/spherical_wrist_2_link.STL" />
        </geometry>
      </collision>
    </link>

    <link name="bracelet_link">
      <inertial>
        <origin xyz="-0.000281 -0.011402 -0.029798" rpy="0 0 0" />
        <mass value="0.5006" />
        <inertia ixx="0.000587" ixy="3E-06" ixz="3E-06" iyy="0.000369" iyz="0.000118" izz="0.000609" />
      </inertial>
      <visual>
        <origin xyz="0 0 0" rpy="0 0 0" />
        <geometry>
          <mesh filename="package://kortex_description/arms/gen3/meshes/bracelet_link.STL" />
        </geometry>
        <material name="">
          <color rgba="0.75294 0.75294 0.75294 1" />
        </material>
      </visual>
      <collision>
        <origin xyz="0 0 0" rpy="0 0 0" />
        <geometry>
          <mesh filename="package://kortex_description/arms/gen3/meshes/bracelet_link.STL" />
        </geometry>
      </collision>
    </link>


    <link name="end_effector_link" />

    <joint name="joint_1" type="prismatic">
      <origin xyz="0 0 0" rpy="0 0 0" />
      <parent
        link="base_link" />
      <child
        link="x_prismatic" />
      <axis
        xyz="1 0 0" />
      <limit lower="-2.1" upper="2.1" effort="39" velocity="0.8727" />
    </joint>

    <joint name="joint_2" type="prismatic">
      <origin xyz="0 0 0" rpy="0 0 0" />
      <parent
        link="x_prismatic" />
      <child
        link="y_prismatic" />
      <axis
        xyz="0 1 0" />
      <limit lower="-2.1" upper="2.1" effort="39" velocity="0.8727" />
    </joint>

    <joint name="joint_3" type="continuous">
      <origin xyz="0 0 0" rpy="0 0 0" />
      <parent
        link="y_prismatic" />
      <child
        link="mmp_base" />
      <axis
        xyz="0 0 1" />
      <limit
        effort="39"
        velocity="0.8727" />
    </joint>

    <joint name="joint_4" type="continuous">
      <origin xyz="0 0 0.48643" rpy="3.1416 2.7629E-18 -3.14" />
      <parent
        link="mmp_base" />
      <child
        link="shoulder_link" />
      <axis
        xyz="0 0 1" />
      <limit
        effort="39"
        velocity="0.8727" />
    </joint>

    <joint name="joint_5" type="revolute">
      <origin xyz="0 0.005375 -0.12838" rpy="1.5708 2.1343E-17 -1.1102E-16" />
      <parent
        link="shoulder_link" />
      <child
        link="half_arm_1_link" />
      <axis
        xyz="0 0 1" />
      <!-- <limit lower="-2.41" upper="2.41" effort="39" velocity="0.8727" /> -->
      <limit lower="-2.1" upper="2.1" effort="39" velocity="0.8727" />

    </joint>

    <joint name="joint_6" type="continuous">
      <origin xyz="0 -0.21038 -0.006375" rpy="-1.5708 1.2326E-32 -2.9122E-16" />
      <parent
        link="half_arm_1_link" />
      <child
        link="half_arm_2_link" />
      <axis
        xyz="0 0 1" />
      <limit
        effort="39"
        velocity="0.8727" />
    </joint>

    <joint name="joint_7" type="revolute">
      <origin xyz="0 0.006375 -0.21038" rpy="1.5708 -6.6954E-17 -1.6653E-16" />
      <parent
        link="half_arm_2_link" />
      <child
        link="forearm_link" />
      <axis
        xyz="0 0 1" />
      <!-- <limit lower="-2.66" upper="2.66" effort="39" velocity="0.8727" /> -->
      <limit lower="-2.1" upper="2.1" effort="39" velocity="0.8727" />
    </joint>


    <joint name="joint_8" type="continuous">
      <origin xyz="0 -0.20843 -0.006375" rpy="-1.5708 2.2204E-16 -6.373E-17" />
      <parent
        link="forearm_link" />
      <child
        link="spherical_wrist_1_link" />
      <axis
        xyz="0 0 1" />
      <limit
        effort="9"
        velocity="0.8727" />
    </joint>


    <joint name="joint_9" type="revolute">
      <origin xyz="0 0.00017505 -0.10593" rpy="1.5708 9.2076E-28 -8.2157E-15" />
      <parent
        link="spherical_wrist_1_link" />
      <child
        link="spherical_wrist_2_link" />
      <axis
        xyz="0 0 1" />
<!--       <limit lower="-2.23" upper="2.23" effort="9" velocity="0.8727" /> -->
      <limit lower="-1.9" upper="1.9" effort="9" velocity="0.8727" />
    </joint>


    <joint name="joint_10" type="continuous">
      <origin xyz="0 -0.10593 -0.00017505" rpy="-1.5708 -5.5511E-17 9.6396E-17" />
      <parent
        link="spherical_wrist_2_link" />
      <child
        link="bracelet_link" />
      <axis
        xyz="0 0 1" />
      <limit
        effort="9"
        velocity="0.8727" />
    </joint>


    <joint name="end_effector" type="fixed">
      <origin xyz="0 0 -0.0615250000000001" rpy="0 0 0" />
      <parent
        link="bracelet_link" />
      <child
        link="end_effector_link" />
      <axis
        xyz="0 0 0" />
    </joint>

  </xacro:macro>
</robot>
